{
    "correct": 0,
    "error": "[NbClientApp] Executing .laborantum/texts/course/0-Warmup/2. Matrix Algebra/1-Matrices-Manual-Exercise/task.ipynb\n[NbClientApp] ERROR | Notebook JSON is invalid: Additional properties are not allowed ('outputs' was unexpected)\n\nFailed validating 'additionalProperties' in markdown_cell:\n\nOn instance['cells'][1]:\n{'cell_type': 'markdown',\n 'id': '41393305',\n 'metadata': {},\n 'outputs': ['...0 outputs...'],\n 'source': '# Task\\n'\n           '\\n'\n           'Perform the following operations:\\n'\n           '\\n'\n           '$$ 5 \\\\begin{bmatrix} ...'}\n0.00s - Debugger warning: It seems that frozen modules are being used, which may\n0.00s - make the debugger miss breakpoints. Please pass -Xfrozen_modules=off\n0.00s - to python to disable frozen modules.\n0.00s - Note: Debugging will proceed. Set PYDEVD_DISABLE_FILE_VALIDATION=1 to disable this validation.\n[NbClientApp] Executing notebook with kernel: container_env\nTraceback (most recent call last):\n  File \"/usr/local/lib/python3.11/site-packages/jupyter_core/utils/__init__.py\", line 154, in wrapped\n    asyncio.get_running_loop()\nRuntimeError: no running event loop\n\nDuring handling of the above exception, another exception occurred:\n\nTraceback (most recent call last):\n  File \"/usr/local/bin/jupyter-execute\", line 8, in <module>\n    sys.exit(main())\n             ^^^^^^\n  File \"/usr/local/lib/python3.11/site-packages/jupyter_core/application.py\", line 284, in launch_instance\n    super().launch_instance(argv=argv, **kwargs)\n  File \"/usr/local/lib/python3.11/site-packages/traitlets/config/application.py\", line 1074, in launch_instance\n    app.initialize(argv)\n  File \"/usr/local/lib/python3.11/site-packages/traitlets/config/application.py\", line 118, in inner\n    return method(app, *args, **kwargs)\n           ^^^^^^^^^^^^^^^^^^^^^^^^^^^^\n  File \"/usr/local/lib/python3.11/site-packages/nbclient/cli.py\", line 161, in initialize\n    self.run_notebook(path)\n  File \"/usr/local/lib/python3.11/site-packages/nbclient/cli.py\", line 215, in run_notebook\n    client.execute()\n  File \"/usr/local/lib/python3.11/site-packages/jupyter_core/utils/__init__.py\", line 158, in wrapped\n    return loop.run_until_complete(inner)\n           ^^^^^^^^^^^^^^^^^^^^^^^^^^^^^^\n  File \"/usr/local/lib/python3.11/asyncio/base_events.py\", line 654, in run_until_complete\n    return future.result()\n           ^^^^^^^^^^^^^^^\n  File \"/usr/local/lib/python3.11/site-packages/nbclient/client.py\", line 709, in async_execute\n    await self.async_execute_cell(\n  File \"/usr/local/lib/python3.11/site-packages/nbclient/client.py\", line 1062, in async_execute_cell\n    await self._check_raise_for_error(cell, cell_index, exec_reply)\n  File \"/usr/local/lib/python3.11/site-packages/nbclient/client.py\", line 918, in _check_raise_for_error\n    raise CellExecutionError.from_cell_and_msg(cell, exec_reply_content)\nnbclient.exceptions.CellExecutionError: An error occurred while executing the following cell:\n------------------\nanswer['task1'] = np.array(\n    ## YOUR ANSWER HERE\n)\n------------------\n\n\n\u001b[31m---------------------------------------------------------------------------\u001b[39m\n\u001b[31mTypeError\u001b[39m                                 Traceback (most recent call last)\n\u001b[36mCell\u001b[39m\u001b[36m \u001b[39m\u001b[32mIn[2]\u001b[39m\u001b[32m, line 1\u001b[39m\n\u001b[32m----> \u001b[39m\u001b[32m1\u001b[39m answer[\u001b[33m'\u001b[39m\u001b[33mtask1\u001b[39m\u001b[33m'\u001b[39m] = \u001b[43mnp\u001b[49m\u001b[43m.\u001b[49m\u001b[43marray\u001b[49m\u001b[43m(\u001b[49m\n\u001b[32m      2\u001b[39m \u001b[43m    \u001b[49m\u001b[38;5;66;43;03m## YOUR ANSWER HERE\u001b[39;49;00m\n\u001b[32m      3\u001b[39m \u001b[43m)\u001b[49m\n\n\u001b[31mTypeError\u001b[39m: array() missing required argument 'object' (pos 0)\n\n"
}